[2024-10-22T22:33:44.421+0000] {local_task_job_runner.py:120} INFO - ::group::Pre task execution logs
[2024-10-22T22:33:44.445+0000] {taskinstance.py:2076} INFO - Dependencies all met for dep_context=non-requeueable deps ti=<TaskInstance: DataPipeline.load_data_task manual__2024-10-22T22:33:40.262408+00:00 [queued]>
[2024-10-22T22:33:44.451+0000] {taskinstance.py:2076} INFO - Dependencies all met for dep_context=requeueable deps ti=<TaskInstance: DataPipeline.load_data_task manual__2024-10-22T22:33:40.262408+00:00 [queued]>
[2024-10-22T22:33:44.459+0000] {taskinstance.py:2306} INFO - Starting attempt 1 of 3
[2024-10-22T22:33:44.473+0000] {taskinstance.py:2330} INFO - Executing <Task(PythonOperator): load_data_task> on 2024-10-22 22:33:40.262408+00:00
[2024-10-22T22:33:44.479+0000] {warnings.py:112} WARNING - /home/***/.local/lib/python3.12/site-packages/***/task/task_runner/standard_task_runner.py:61: DeprecationWarning: This process (pid=73) is multi-threaded, use of fork() may lead to deadlocks in the child.
  pid = os.fork()

[2024-10-22T22:33:44.481+0000] {standard_task_runner.py:63} INFO - Started process 75 to run task
[2024-10-22T22:33:44.480+0000] {standard_task_runner.py:90} INFO - Running: ['***', 'tasks', 'run', 'DataPipeline', 'load_data_task', 'manual__2024-10-22T22:33:40.262408+00:00', '--job-id', '4', '--raw', '--subdir', 'DAGS_FOLDER/src/***.py', '--cfg-path', '/tmp/tmpifyvr6k_']
[2024-10-22T22:33:44.482+0000] {standard_task_runner.py:91} INFO - Job 4: Subtask load_data_task
[2024-10-22T22:33:44.543+0000] {task_command.py:426} INFO - Running <TaskInstance: DataPipeline.load_data_task manual__2024-10-22T22:33:40.262408+00:00 [running]> on host 7b75a9f07e3d
[2024-10-22T22:33:44.637+0000] {taskinstance.py:2648} INFO - Exporting env vars: AIRFLOW_CTX_DAG_OWNER='MLopsProjectGroup6' AIRFLOW_CTX_DAG_ID='DataPipeline' AIRFLOW_CTX_TASK_ID='load_data_task' AIRFLOW_CTX_EXECUTION_DATE='2024-10-22T22:33:40.262408+00:00' AIRFLOW_CTX_TRY_NUMBER='1' AIRFLOW_CTX_DAG_RUN_ID='manual__2024-10-22T22:33:40.262408+00:00'
[2024-10-22T22:33:44.640+0000] {taskinstance.py:430} INFO - ::endgroup::
[2024-10-22T22:33:44.665+0000] {LoadData.py:26} INFO - Project directory fetched successfully
[2024-10-22T22:33:44.669+0000] {LoadData.py:45} ERROR - An unexpected error occurred: [Errno 2] No such file or directory: '/opt/***/dags/data/processed/raw_data.pkl'
[2024-10-22T22:33:44.670+0000] {python.py:237} INFO - Done. Returned value was: None
[2024-10-22T22:33:44.670+0000] {taskinstance.py:441} INFO - ::group::Post task execution logs
[2024-10-22T22:33:44.680+0000] {taskinstance.py:1206} INFO - Marking task as SUCCESS. dag_id=DataPipeline, task_id=load_data_task, run_id=manual__2024-10-22T22:33:40.262408+00:00, execution_date=20241022T223340, start_date=20241022T223344, end_date=20241022T223344
[2024-10-22T22:33:44.736+0000] {local_task_job_runner.py:240} INFO - Task exited with return code 0
[2024-10-22T22:33:44.752+0000] {taskinstance.py:3503} INFO - 0 downstream tasks scheduled from follow-on schedule check
[2024-10-22T22:33:44.771+0000] {local_task_job_runner.py:222} INFO - ::endgroup::
