[2024-10-23T16:10:54.827+0000] {local_task_job_runner.py:120} INFO - ::group::Pre task execution logs
[2024-10-23T16:10:54.855+0000] {taskinstance.py:2076} INFO - Dependencies all met for dep_context=non-requeueable deps ti=<TaskInstance: DataPipeline.process_data manual__2024-10-23T16:10:44.482765+00:00 [queued]>
[2024-10-23T16:10:54.867+0000] {taskinstance.py:2076} INFO - Dependencies all met for dep_context=requeueable deps ti=<TaskInstance: DataPipeline.process_data manual__2024-10-23T16:10:44.482765+00:00 [queued]>
[2024-10-23T16:10:54.870+0000] {taskinstance.py:2306} INFO - Starting attempt 1 of 3
[2024-10-23T16:10:54.889+0000] {taskinstance.py:2330} INFO - Executing <Task(PythonOperator): process_data> on 2024-10-23 16:10:44.482765+00:00
[2024-10-23T16:10:54.898+0000] {warnings.py:112} WARNING - /home/***/.local/lib/python3.12/site-packages/***/task/task_runner/standard_task_runner.py:61: DeprecationWarning: This process (pid=528) is multi-threaded, use of fork() may lead to deadlocks in the child.
  pid = os.fork()

[2024-10-23T16:10:54.900+0000] {standard_task_runner.py:63} INFO - Started process 530 to run task
[2024-10-23T16:10:54.900+0000] {standard_task_runner.py:90} INFO - Running: ['***', 'tasks', 'run', 'DataPipeline', 'process_data', 'manual__2024-10-23T16:10:44.482765+00:00', '--job-id', '84', '--raw', '--subdir', 'DAGS_FOLDER/src/***.py', '--cfg-path', '/tmp/tmp7rle6oe0']
[2024-10-23T16:10:54.904+0000] {standard_task_runner.py:91} INFO - Job 84: Subtask process_data
[2024-10-23T16:10:54.963+0000] {task_command.py:426} INFO - Running <TaskInstance: DataPipeline.process_data manual__2024-10-23T16:10:44.482765+00:00 [running]> on host 6c58daef65ee
[2024-10-23T16:10:55.095+0000] {taskinstance.py:2648} INFO - Exporting env vars: AIRFLOW_CTX_DAG_OWNER='MLopsProjectGroup6' AIRFLOW_CTX_DAG_ID='DataPipeline' AIRFLOW_CTX_TASK_ID='process_data' AIRFLOW_CTX_EXECUTION_DATE='2024-10-23T16:10:44.482765+00:00' AIRFLOW_CTX_TRY_NUMBER='1' AIRFLOW_CTX_DAG_RUN_ID='manual__2024-10-23T16:10:44.482765+00:00'
[2024-10-23T16:10:55.102+0000] {taskinstance.py:430} INFO - ::endgroup::
[2024-10-23T16:10:55.149+0000] {HandlingNullValues.py:24} INFO - Loading CSV data for processing
[2024-10-23T16:10:55.158+0000] {HandlingNullValues.py:47} ERROR - An unexpected error occurred during data processing: [Errno 2] No such file or directory: '/opt/***/dags/src/../data/processed/raw_data.csv'
[2024-10-23T16:10:55.160+0000] {python.py:237} INFO - Done. Returned value was: None
[2024-10-23T16:10:55.161+0000] {taskinstance.py:441} INFO - ::group::Post task execution logs
[2024-10-23T16:10:55.180+0000] {taskinstance.py:1206} INFO - Marking task as SUCCESS. dag_id=DataPipeline, task_id=process_data, run_id=manual__2024-10-23T16:10:44.482765+00:00, execution_date=20241023T161044, start_date=20241023T161054, end_date=20241023T161055
[2024-10-23T16:10:55.236+0000] {local_task_job_runner.py:240} INFO - Task exited with return code 0
[2024-10-23T16:10:55.267+0000] {taskinstance.py:3503} INFO - 0 downstream tasks scheduled from follow-on schedule check
[2024-10-23T16:10:55.271+0000] {local_task_job_runner.py:222} INFO - ::endgroup::
