[2024-10-26T08:54:15.714+0000] {local_task_job_runner.py:120} INFO - ::group::Pre task execution logs
[2024-10-26T08:54:15.727+0000] {taskinstance.py:2076} INFO - Dependencies all met for dep_context=non-requeueable deps ti=<TaskInstance: DataPipeline.download_data_from_gcp manual__2024-10-26T08:54:14.101503+00:00 [queued]>
[2024-10-26T08:54:15.731+0000] {taskinstance.py:2076} INFO - Dependencies all met for dep_context=requeueable deps ti=<TaskInstance: DataPipeline.download_data_from_gcp manual__2024-10-26T08:54:14.101503+00:00 [queued]>
[2024-10-26T08:54:15.732+0000] {taskinstance.py:2306} INFO - Starting attempt 1 of 3
[2024-10-26T08:54:15.740+0000] {taskinstance.py:2330} INFO - Executing <Task(PythonOperator): download_data_from_gcp> on 2024-10-26 08:54:14.101503+00:00
[2024-10-26T08:54:15.744+0000] {warnings.py:112} WARNING - /home/***/.local/lib/python3.12/site-packages/***/task/task_runner/standard_task_runner.py:61: DeprecationWarning: This process (pid=135) is multi-threaded, use of fork() may lead to deadlocks in the child.
  pid = os.fork()

[2024-10-26T08:54:15.745+0000] {standard_task_runner.py:63} INFO - Started process 137 to run task
[2024-10-26T08:54:15.747+0000] {standard_task_runner.py:90} INFO - Running: ['***', 'tasks', 'run', 'DataPipeline', 'download_data_from_gcp', 'manual__2024-10-26T08:54:14.101503+00:00', '--job-id', '143', '--raw', '--subdir', 'DAGS_FOLDER/src/***.py', '--cfg-path', '/tmp/tmpx0rldl3u']
[2024-10-26T08:54:15.748+0000] {standard_task_runner.py:91} INFO - Job 143: Subtask download_data_from_gcp
[2024-10-26T08:54:15.769+0000] {task_command.py:426} INFO - Running <TaskInstance: DataPipeline.download_data_from_gcp manual__2024-10-26T08:54:14.101503+00:00 [running]> on host 558a41ea7330
[2024-10-26T08:54:15.814+0000] {taskinstance.py:2648} INFO - Exporting env vars: AIRFLOW_CTX_DAG_OWNER='MLopsProjectGroup6' AIRFLOW_CTX_DAG_ID='DataPipeline' AIRFLOW_CTX_TASK_ID='download_data_from_gcp' AIRFLOW_CTX_EXECUTION_DATE='2024-10-26T08:54:14.101503+00:00' AIRFLOW_CTX_TRY_NUMBER='1' AIRFLOW_CTX_DAG_RUN_ID='manual__2024-10-26T08:54:14.101503+00:00'
[2024-10-26T08:54:15.815+0000] {taskinstance.py:430} INFO - ::endgroup::
[2024-10-26T08:54:15.828+0000] {DownloadData.py:31} INFO - Starting data download process
[2024-10-26T08:54:15.829+0000] {DownloadData.py:32} INFO - Starting data download process
[2024-10-26T08:54:15.831+0000] {DownloadData.py:34} ERROR - An unexpected error occurred: File /opt/***/config/key.json was not found.
[2024-10-26T08:54:15.831+0000] {DownloadData.py:35} ERROR - An unexpected error occurred: File /opt/***/config/key.json was not found.
[2024-10-26T08:54:15.832+0000] {python.py:237} INFO - Done. Returned value was: None
[2024-10-26T08:54:15.833+0000] {taskinstance.py:441} INFO - ::group::Post task execution logs
[2024-10-26T08:54:15.839+0000] {taskinstance.py:1206} INFO - Marking task as SUCCESS. dag_id=DataPipeline, task_id=download_data_from_gcp, run_id=manual__2024-10-26T08:54:14.101503+00:00, execution_date=20241026T085414, start_date=20241026T085415, end_date=20241026T085415
[2024-10-26T08:54:15.887+0000] {local_task_job_runner.py:240} INFO - Task exited with return code 0
[2024-10-26T08:54:15.901+0000] {taskinstance.py:3503} INFO - 1 downstream tasks scheduled from follow-on schedule check
[2024-10-26T08:54:15.901+0000] {local_task_job_runner.py:222} INFO - ::endgroup::
