[2024-10-26T09:10:30.200+0000] {local_task_job_runner.py:120} INFO - ::group::Pre task execution logs
[2024-10-26T09:10:30.211+0000] {taskinstance.py:2076} INFO - Dependencies all met for dep_context=non-requeueable deps ti=<TaskInstance: DataPipeline.pre_process_data manual__2024-10-26T09:02:42.447256+00:00 [queued]>
[2024-10-26T09:10:30.220+0000] {taskinstance.py:2076} INFO - Dependencies all met for dep_context=requeueable deps ti=<TaskInstance: DataPipeline.pre_process_data manual__2024-10-26T09:02:42.447256+00:00 [queued]>
[2024-10-26T09:10:30.220+0000] {taskinstance.py:2306} INFO - Starting attempt 1 of 3
[2024-10-26T09:10:30.226+0000] {taskinstance.py:2330} INFO - Executing <Task(PythonOperator): pre_process_data> on 2024-10-26 09:02:42.447256+00:00
[2024-10-26T09:10:30.232+0000] {warnings.py:112} WARNING - /home/***/.local/lib/python3.12/site-packages/***/task/task_runner/standard_task_runner.py:61: DeprecationWarning: This process (pid=82) is multi-threaded, use of fork() may lead to deadlocks in the child.
  pid = os.fork()

[2024-10-26T09:10:30.234+0000] {standard_task_runner.py:63} INFO - Started process 84 to run task
[2024-10-26T09:10:30.233+0000] {standard_task_runner.py:90} INFO - Running: ['***', 'tasks', 'run', 'DataPipeline', 'pre_process_data', 'manual__2024-10-26T09:02:42.447256+00:00', '--job-id', '162', '--raw', '--subdir', 'DAGS_FOLDER/src/***.py', '--cfg-path', '/tmp/tmpu_ibm66e']
[2024-10-26T09:10:30.235+0000] {standard_task_runner.py:91} INFO - Job 162: Subtask pre_process_data
[2024-10-26T09:10:30.261+0000] {task_command.py:426} INFO - Running <TaskInstance: DataPipeline.pre_process_data manual__2024-10-26T09:02:42.447256+00:00 [running]> on host 558a41ea7330
[2024-10-26T09:10:30.319+0000] {taskinstance.py:2648} INFO - Exporting env vars: AIRFLOW_CTX_DAG_OWNER='MLopsProjectGroup6' AIRFLOW_CTX_DAG_ID='DataPipeline' AIRFLOW_CTX_TASK_ID='pre_process_data' AIRFLOW_CTX_EXECUTION_DATE='2024-10-26T09:02:42.447256+00:00' AIRFLOW_CTX_TRY_NUMBER='1' AIRFLOW_CTX_DAG_RUN_ID='manual__2024-10-26T09:02:42.447256+00:00'
[2024-10-26T09:10:30.320+0000] {taskinstance.py:430} INFO - ::endgroup::
[2024-10-26T09:10:30.328+0000] {datatype_format.py:65} INFO - Starting data processing
[2024-10-26T09:10:30.329+0000] {datatype_format.py:66} INFO - Input file: /opt/***/data/processed/processed_data.pkl
[2024-10-26T09:10:30.341+0000] {datatype_format.py:83} INFO - Loaded data from /opt/***/data/processed/processed_data.pkl with shape (45211, 1)
[2024-10-26T09:10:30.342+0000] {datatype_format.py:33} INFO - Checking data types of the dataset.
[2024-10-26T09:10:30.361+0000] {datatype_format.py:38} INFO - Saved BEFORE conversion data type information to /opt/***/data/processed/datatype_info_before.csv
[2024-10-26T09:10:30.386+0000] {datatype_format.py:53} INFO - Saved AFTER conversion data type information to /opt/***/data/processed/datatype_info_after.csv
[2024-10-26T09:10:30.401+0000] {datatype_format.py:93} INFO - Processed data saved as pickle at /opt/***/data/processed/datatype_format_processed.pkl
[2024-10-26T09:10:30.401+0000] {datatype_format.py:95} INFO - Data processing completed successfully
[2024-10-26T09:10:30.402+0000] {outlier_handing.py:88} INFO - Starting outlier handling process
[2024-10-26T09:10:30.402+0000] {outlier_handing.py:89} INFO - Input file: /opt/***/data/processed/datatype_format_processed.pkl
[2024-10-26T09:10:30.406+0000] {outlier_handing.py:94} INFO - Loaded data from /opt/***/data/processed/datatype_format_processed.pkl with shape (45211, 1)
[2024-10-26T09:10:30.406+0000] {outlier_handing.py:56} INFO - Starting outlier handling.
[2024-10-26T09:10:30.407+0000] {outlier_handing.py:79} INFO - Outlier handling completed.
[2024-10-26T09:10:30.408+0000] {outlier_handing.py:110} ERROR - Error occurred: Cannot save file into a non-existent directory: '/opt/***/dags/data/processed'
[2024-10-26T09:10:30.408+0000] {taskinstance.py:441} INFO - ::group::Post task execution logs
[2024-10-26T09:10:30.408+0000] {taskinstance.py:2905} ERROR - Task failed with exception
Traceback (most recent call last):
  File "/home/airflow/.local/lib/python3.12/site-packages/airflow/models/taskinstance.py", line 465, in _execute_task
    result = _execute_callable(context=context, **execute_callable_kwargs)
             ^^^^^^^^^^^^^^^^^^^^^^^^^^^^^^^^^^^^^^^^^^^^^^^^^^^^^^^^^^^^^
  File "/home/airflow/.local/lib/python3.12/site-packages/airflow/models/taskinstance.py", line 432, in _execute_callable
    return execute_callable(context=context, **execute_callable_kwargs)
           ^^^^^^^^^^^^^^^^^^^^^^^^^^^^^^^^^^^^^^^^^^^^^^^^^^^^^^^^^^^^
  File "/home/airflow/.local/lib/python3.12/site-packages/airflow/models/baseoperator.py", line 401, in wrapper
    return func(self, *args, **kwargs)
           ^^^^^^^^^^^^^^^^^^^^^^^^^^^
  File "/home/airflow/.local/lib/python3.12/site-packages/airflow/operators/python.py", line 235, in execute
    return_value = self.execute_callable()
                   ^^^^^^^^^^^^^^^^^^^^^^^
  File "/home/airflow/.local/lib/python3.12/site-packages/airflow/operators/python.py", line 252, in execute_callable
    return self.python_callable(*self.op_args, **self.op_kwargs)
           ^^^^^^^^^^^^^^^^^^^^^^^^^^^^^^^^^^^^^^^^^^^^^^^^^^^^^
  File "/opt/airflow/dags/src/data_preprocessing/preprocessing_main.py", line 23, in preprocess_data
    data = process_outlier_handling(data)
           ^^^^^^^^^^^^^^^^^^^^^^^^^^^^^^
  File "/opt/airflow/dags/src/data_preprocessing/outlier_handing.py", line 103, in process_outlier_handling
    data_handled.to_pickle(OUTPUT_FILE_PATH)
  File "/home/airflow/.local/lib/python3.12/site-packages/pandas/core/generic.py", line 3085, in to_pickle
    to_pickle(
  File "/home/airflow/.local/lib/python3.12/site-packages/pandas/io/pickle.py", line 105, in to_pickle
    with get_handle(
         ^^^^^^^^^^^
  File "/home/airflow/.local/lib/python3.12/site-packages/pandas/io/common.py", line 739, in get_handle
    check_parent_directory(str(handle))
  File "/home/airflow/.local/lib/python3.12/site-packages/pandas/io/common.py", line 604, in check_parent_directory
    raise OSError(rf"Cannot save file into a non-existent directory: '{parent}'")
OSError: Cannot save file into a non-existent directory: '/opt/***/dags/data/processed'
[2024-10-26T09:10:30.419+0000] {taskinstance.py:1206} INFO - Marking task as UP_FOR_RETRY. dag_id=DataPipeline, task_id=pre_process_data, run_id=manual__2024-10-26T09:02:42.447256+00:00, execution_date=20241026T090242, start_date=20241026T091030, end_date=20241026T091030
[2024-10-26T09:10:30.425+0000] {standard_task_runner.py:110} ERROR - Failed to execute job 162 for task pre_process_data (Cannot save file into a non-existent directory: '/opt/***/dags/data/processed'; 84)
[2024-10-26T09:10:30.461+0000] {local_task_job_runner.py:240} INFO - Task exited with return code 1
[2024-10-26T09:10:30.475+0000] {taskinstance.py:3503} INFO - 0 downstream tasks scheduled from follow-on schedule check
[2024-10-26T09:10:30.476+0000] {local_task_job_runner.py:222} INFO - ::endgroup::
