[2024-10-23T02:12:38.183+0000] {local_task_job_runner.py:120} INFO - ::group::Pre task execution logs
[2024-10-23T02:12:38.208+0000] {taskinstance.py:2076} INFO - Dependencies all met for dep_context=non-requeueable deps ti=<TaskInstance: DataPipeline.load_data manual__2024-10-23T02:12:32.475913+00:00 [queued]>
[2024-10-23T02:12:38.218+0000] {taskinstance.py:2076} INFO - Dependencies all met for dep_context=requeueable deps ti=<TaskInstance: DataPipeline.load_data manual__2024-10-23T02:12:32.475913+00:00 [queued]>
[2024-10-23T02:12:38.220+0000] {taskinstance.py:2306} INFO - Starting attempt 1 of 3
[2024-10-23T02:12:38.234+0000] {taskinstance.py:2330} INFO - Executing <Task(PythonOperator): load_data> on 2024-10-23 02:12:32.475913+00:00
[2024-10-23T02:12:38.241+0000] {warnings.py:112} WARNING - /home/***/.local/lib/python3.12/site-packages/***/task/task_runner/standard_task_runner.py:61: DeprecationWarning: This process (pid=107) is multi-threaded, use of fork() may lead to deadlocks in the child.
  pid = os.fork()

[2024-10-23T02:12:38.243+0000] {standard_task_runner.py:63} INFO - Started process 109 to run task
[2024-10-23T02:12:38.243+0000] {standard_task_runner.py:90} INFO - Running: ['***', 'tasks', 'run', 'DataPipeline', 'load_data', 'manual__2024-10-23T02:12:32.475913+00:00', '--job-id', '7', '--raw', '--subdir', 'DAGS_FOLDER/src/***.py', '--cfg-path', '/tmp/tmp941py0ej']
[2024-10-23T02:12:38.246+0000] {standard_task_runner.py:91} INFO - Job 7: Subtask load_data
[2024-10-23T02:12:38.303+0000] {task_command.py:426} INFO - Running <TaskInstance: DataPipeline.load_data manual__2024-10-23T02:12:32.475913+00:00 [running]> on host 086019f7b15d
[2024-10-23T02:12:38.465+0000] {taskinstance.py:2648} INFO - Exporting env vars: AIRFLOW_CTX_DAG_OWNER='MLopsProjectGroup6' AIRFLOW_CTX_DAG_ID='DataPipeline' AIRFLOW_CTX_TASK_ID='load_data' AIRFLOW_CTX_EXECUTION_DATE='2024-10-23T02:12:32.475913+00:00' AIRFLOW_CTX_TRY_NUMBER='1' AIRFLOW_CTX_DAG_RUN_ID='manual__2024-10-23T02:12:32.475913+00:00'
[2024-10-23T02:12:38.467+0000] {taskinstance.py:430} INFO - ::endgroup::
[2024-10-23T02:12:38.488+0000] {LoadData.py:26} INFO - Project directory fetched successfully
[2024-10-23T02:12:38.489+0000] {LoadData.py:45} ERROR - An unexpected error occurred: [Errno 2] No such file or directory: 'True'
[2024-10-23T02:12:38.490+0000] {python.py:237} INFO - Done. Returned value was: False
[2024-10-23T02:12:38.491+0000] {taskinstance.py:441} INFO - ::group::Post task execution logs
[2024-10-23T02:12:38.515+0000] {taskinstance.py:1206} INFO - Marking task as SUCCESS. dag_id=DataPipeline, task_id=load_data, run_id=manual__2024-10-23T02:12:32.475913+00:00, execution_date=20241023T021232, start_date=20241023T021238, end_date=20241023T021238
[2024-10-23T02:12:38.578+0000] {local_task_job_runner.py:240} INFO - Task exited with return code 0
[2024-10-23T02:12:38.605+0000] {taskinstance.py:3503} INFO - 0 downstream tasks scheduled from follow-on schedule check
[2024-10-23T02:12:38.611+0000] {local_task_job_runner.py:222} INFO - ::endgroup::
